<?xml version="1.0"?>
<robot name="U-CAT">
	<link name="base_link">
		<visual>
			<geometry>
				<mesh filename="package://uwsim_arrows/data/meshes/ArrowsBody.dae"/>
        	</geometry>
		</visual>
		<collision>
			<geometry>
				<cylinder radius="0.35" length="0.30" />
			</geometry>
		</collision>
	</link>
	
	<!-- motor 1 -->
	<link name="frontrightflipper">
		<visual>
			<origin rpy="0 0 0" xyz="-0.092 0.06 0" />
			<geometry>
				<mesh filename="package://uwsim_arrows/data/meshes/ArrowsFin.dae"/>
        	</geometry>
		</visual>
	</link>
	
	<!-- motor 2 -->
	<link name="backrightflipper">
		<visual>
			<origin rpy="0 0 0" xyz="-0.092 0.06 0" />
			<geometry>
				<mesh filename="package://uwsim_arrows/data/meshes/ArrowsFin.dae"/>
        	</geometry>
		</visual>
	</link>
	
	<!-- motor 3 -->
	<link name="backleftflipper">
		<visual>
			<origin rpy="0 0 0" xyz="-0.092 0.06 0" />
			<geometry>
				<mesh filename="package://uwsim_arrows/data/meshes/ArrowsFin.dae"/>
        	</geometry>
		</visual>
	</link>
	
	<!-- motor 4 -->
	<link name="frontleftflipper">
		<visual>
			<origin rpy="0 0 0" xyz="-0.092 0.06 0" />
			<geometry>
				<mesh filename="package://uwsim_arrows/data/meshes/ArrowsFin.dae"/>
        	</geometry>
		</visual>
	</link>
	
	<!-- sonars -->
	<link name="sonar_b">
		<visual>
			<geometry>
				<mesh filename="package://uwsim_arrows/data/meshes/Sonar.dae"/>
        	</geometry>
		</visual>
	</link>
	<link name="sonar_ff">
		<visual>
			<geometry>
				<mesh filename="package://uwsim_arrows/data/meshes/Sonar.dae"/>
        	</geometry>
		</visual>
	</link>
	<link name="sonar_fl">
		<visual>
			<geometry>
				<mesh filename="package://uwsim_arrows/data/meshes/Sonar.dae"/>
        	</geometry>
		</visual>
	</link>
	<link name="sonar_fr">
		<visual>
			<geometry>
				<mesh filename="package://uwsim_arrows/data/meshes/Sonar.dae"/>
        	</geometry>
		</visual>
	</link>
	<link name="sonar_fu">
		<visual>
			<geometry>
				<mesh filename="package://uwsim_arrows/data/meshes/Sonar.dae"/>
        	</geometry>
		</visual>
	</link>
	<link name="sonar_fd">
		<visual>
			<geometry>
				<mesh filename="package://uwsim_arrows/data/meshes/Sonar.dae"/>
        	</geometry>
		</visual>
	</link>
	<link name="sonar_l">
		<visual>
			<geometry>
				<mesh filename="package://uwsim_arrows/data/meshes/Sonar.dae"/>
        	</geometry>
		</visual>
	</link>
	<link name="sonar_r">
		<visual>
			<geometry>
				<mesh filename="package://uwsim_arrows/data/meshes/Sonar.dae"/>
        	</geometry>
		</visual>
	</link>

	<!-- narrow sonars -->
	
	<link name="sonar_ff_0_0">
		<visual>
			<geometry>
				<box size="0.0 0.0 0.0"/>
        	</geometry>
		</visual>
	</link>
	
	<link name="sonar_ff_0_6">
		<visual>
			<geometry>
				<box size="0.0 0.0 0.0"/>
        	</geometry>
		</visual>
	</link>

	<link name="sonar_ff_6_6">
		<visual>
			<geometry>
				<box size="0.0 0.0 0.0"/>
        	</geometry>
		</visual>
	</link>
	
	<link name="sonar_ff_6_0">
		<visual>
			<geometry>
				<box size="0.0 0.0 0.0"/>
        	</geometry>
		</visual>
	</link>
	
	<link name="sonar_ff_0_3">
		<visual>
			<geometry>
				<box size="0.0 0.0 0.0"/>
        	</geometry>
		</visual>
	</link>
	<link name="sonar_ff_2_3">
		<visual>
			<geometry>
				<box size="0.0 0.0 0.0"/>
        	</geometry>
		</visual>
	</link>
	<link name="sonar_ff_4_3">
		<visual>
			<geometry>
				<box size="0.0 0.0 0.0"/>
        	</geometry>
		</visual>
	</link>
	<link name="sonar_ff_6_3">
		<visual>
			<geometry>
				<box size="0.0 0.0 0.0"/>
        	</geometry>
		</visual>
	</link>
	
	<link name="sonar_ff_3_0">
		<visual>
			<geometry>
				<box size="0.0 0.0 0.0"/>
        	</geometry>
		</visual>
	</link>
	<link name="sonar_ff_3_2">
		<visual>
			<geometry>
				<box size="0.0 0.0 0.0"/>
        	</geometry>
		</visual>
	</link>
	<link name="sonar_ff_3_4">
		<visual>
			<geometry>
				<box size="0.0 0.0 0.0"/>
        	</geometry>
		</visual>
	</link>
	<link name="sonar_ff_3_6">
		<visual>
			<geometry>
				<box size="0.0 0.0 0.0"/>
        	</geometry>
		</visual>
	</link>
		
	<!-- camera -->
	
	<link name="camera_link">
		<visual>
			<geometry>
				<box size="0.01 0.10 0.07"/>
        	</geometry>
		</visual>
	</link>
	
	<link name="camera_link_optical">
		<visual>
			<geometry>
				<box size="0.01 0.01 0.01"/>
        	</geometry>
		</visual>
	</link>
	
	<!-- joints, START COPYING FROM HERE -->
	
	<joint name="baselink_to_frontrightflipper" type="continuous">
		<parent link="base_link" />
		<child link="frontrightflipper" />
		<origin rpy="0 3.14159 -2.61799388" xyz="0.226 -0.096 0" />
		<axis xyz="0 1 0" />
	</joint>

	<joint name="baselink_to_backrightflipper" type="continuous">
		<parent link="base_link" />
		<child link="backrightflipper" />
		<origin rpy="0 3.14159 2.61799388" xyz="-0.226 -0.096 0" />
		<axis xyz="0 1 0" />
	</joint>
	
	<joint name="baselink_to_backleftflipper" type="continuous">
		<parent link="base_link" />
		<child link="backleftflipper" />
		<origin rpy="0 0 0.523598776" xyz="-0.226 0.096 0" />
		<axis xyz="0 1 0" />
	</joint>
	
	<joint name="baselink_to_frontleftflipper" type="continuous">
		<parent link="base_link" />
		<child link="frontleftflipper" />
		<origin rpy="0 0 -0.523598776" xyz="0.226 0.096 0" />
		<axis xyz="0 1 0" />
	</joint>
	
	<joint name="baselink_to_camera_link" type="fixed">
		<parent link="base_link" />
		<child link="camera_link" />
		<origin rpy="0 0.8 0" xyz="0.24 0 -0.07" />
	</joint>

	<joint name="camera_rgb_optical_joint" type="fixed">
		<origin xyz="0 0 0" rpy="-1.57 0 -1.57" />
		<parent link="camera_link" />
		<child link="camera_link_optical" />
	</joint>
	
	<joint name="baselink_to_sonar_b" type="fixed">
		<parent link="base_link" />
		<child link="sonar_b" />
		<origin rpy="0 0 3.14159" xyz="-0.28 0 0" />
	</joint>
	
	<joint name="baselink_to_sonar_ff" type="fixed">
		<parent link="base_link" />
		<child link="sonar_ff" />
		<origin rpy="0 0 0" xyz="0.28 0 0" />
	</joint>
	
	<joint name="baselink_to_sonar_fl" type="fixed">
		<parent link="base_link" />
		<child link="sonar_fl" />
		<origin rpy="0 0 0.559" xyz="0.263 0.057 0" />
	</joint>
	
	<joint name="baselink_to_sonar_fr" type="fixed">
		<parent link="base_link" />
		<child link="sonar_fr" />
		<origin rpy="0 0 -0.559" xyz="0.263 -0.057 0" />
	</joint>
	
	<joint name="baselink_to_sonar_fu" type="fixed">
		<parent link="base_link" />
		<child link="sonar_fu" />
		<origin rpy="0 -1.57 0" xyz="0.20 0 0.10" />
	</joint>
	
	<joint name="baselink_to_sonar_fd" type="fixed">
		<parent link="base_link" />
		<child link="sonar_fd" />
		<origin rpy="0 1.57 0" xyz="-0.20 0 -0.10" />
	</joint>
	
	<joint name="baselink_to_sonar_l" type="fixed">
		<parent link="base_link" />
		<child link="sonar_l" />
		<origin rpy="0 0 1.57" xyz="0 0.165 0" />
	</joint>
	
	<joint name="baselink_to_sonar_r" type="fixed">
		<parent link="base_link" />
		<child link="sonar_r" />
		<origin rpy="0 0 -1.57" xyz="0 -0.165 0" />
	</joint>


<!-- horizontal array -->
	<joint name="baselink_to_sonar_ff_0_3" type="fixed">
		<parent link="base_link" />
		<child link="sonar_ff_0_3" />
		<origin rpy="0 0 0.785398163" xyz="0.28 0 0" />
	</joint>	
	<joint name="baselink_to_sonar_ff_2_3" type="fixed">
		<parent link="base_link" />
		<child link="sonar_ff_2_3" />
		<origin rpy="0 0 0.261799388" xyz="0.28 0 0" />
	</joint>
	<joint name="baselink_to_sonar_ff_4_3" type="fixed">
		<parent link="base_link" />
		<child link="sonar_ff_4_3" />
		<origin rpy="0 0 -0.261799388" xyz="0.28 0 0" />
	</joint>
	<joint name="baselink_to_sonar_ff_6_3" type="fixed">
		<parent link="base_link" />
		<child link="sonar_ff_6_3" />
		<origin rpy="0 0 -0.785398163" xyz="0.28 0 0" />
	</joint>
	
	<joint name="baselink_to_sonar_ff_3_2" type="fixed">
		<parent link="base_link" />
		<child link="sonar_ff_3_2" />
		<origin rpy="0 -0.261799388 0" xyz="0.28 0 0" />
	</joint>
	<joint name="baselink_to_sonar_ff_3_0" type="fixed">
		<parent link="base_link" />
		<child link="sonar_ff_3_0" />
		<origin rpy="0 -0.785398163 0" xyz="0.28 0 0" />
	</joint>
	
	<joint name="baselink_to_sonar_ff_3_4" type="fixed">
		<parent link="base_link" />
		<child link="sonar_ff_3_4" />
		<origin rpy="0 0.261799388 0" xyz="0.28 0 0" />
	</joint>
	<joint name="baselink_to_sonar_ff_3_6" type="fixed">
		<parent link="base_link" />
		<child link="sonar_ff_3_6" />
		<origin rpy="0 0.785398163 0" xyz="0.28 0 0" />
	</joint>
	
	<joint name="baselink_to_sonar_ff_0_6" type="fixed">
		<parent link="base_link" />
		<child link="sonar_ff_0_6" />
		<origin rpy="0 0.65 0.65" xyz="0.28 0 0" />
	</joint>
	<joint name="baselink_to_sonar_ff_0_0" type="fixed">
		<parent link="base_link" />
		<child link="sonar_ff_0_0" />
		<origin rpy="0 -0.65 0.65" xyz="0.28 0 0" />
	</joint>
	<joint name="baselink_to_sonar_ff_6_6" type="fixed">
		<parent link="base_link" />
		<child link="sonar_ff_6_6" />
		<origin rpy="0 0.65 -0.65" xyz="0.28 0 0" />
	</joint>
	<joint name="baselink_to_sonar_ff_6_0" type="fixed">
		<parent link="base_link" />
		<child link="sonar_ff_6_0" />
		<origin rpy="0 -0.65 -00.65" xyz="0.28 0 0" />
	</joint>
	
</robot>